2021-10-26 14:30:48.428 | INFO     |  5724 | __main__:main:46 | Starting Audio Service
2021-10-26 14:30:48.431 | INFO     |  5724 | mycroft.messagebus.load_config:load_message_bus_config:33 | Loading message bus configs
2021-10-26 14:30:48.437 | INFO     |  5724 | mycroft_bus_client.client.client | Connected
2021-10-26 14:30:48.438 | INFO     |  5724 | mycroft.util.process_utils:start_message_bus_client:155 | Connected to messagebus
2021-10-26 14:30:48.441 | WARNING  |  5724 | mycroft.tts.tts:clear_cache:428 | This method is deprecated, use TextToSpeechCache.clear
2021-10-26 14:30:48.938 | ERROR    |  5724 | mycroft.tts.mimic_tts:validate_connection:226 | Mimic executable not found
2021-10-26 14:30:48.938 | ERROR    |  5724 | mycroft.tts.tts:create:625 | The TTS could not be loaded.
Traceback (most recent call last):
  File "/opt/mycroft-core/mycroft/tts/mimic_tts.py", line 221, in validate_connection
    subprocess.call([mimic_bin, '--version'])
  File "/opt/hostedtoolcache/Python/3.7.12/x64/lib/python3.7/subprocess.py", line 339, in call
    with Popen(*popenargs, **kwargs) as p:
  File "/opt/hostedtoolcache/Python/3.7.12/x64/lib/python3.7/subprocess.py", line 800, in __init__
    restore_signals, start_new_session)
  File "/opt/hostedtoolcache/Python/3.7.12/x64/lib/python3.7/subprocess.py", line 1465, in _execute_child
    executable = os.fsencode(executable)
  File "/opt/hostedtoolcache/Python/3.7.12/x64/lib/python3.7/os.py", line 812, in fsencode
    filename = fspath(filename)  # Does type-checking of `filename`.
TypeError: expected str, bytes or os.PathLike object, not NoneType

The above exception was the direct cause of the following exception:

Traceback (most recent call last):
  File "/opt/mycroft-core/mycroft/tts/tts.py", line 614, in create
    tts.validator.validate()
  File "/opt/mycroft-core/mycroft/tts/tts.py", line 500, in validate
    self.validate_connection()
  File "/opt/mycroft-core/mycroft/tts/mimic_tts.py", line 229, in validate_connection
    from err
Exception: Mimic was not found. Run install-mimic.sh to install it.
2021-10-26 14:30:48.963 | ERROR    |  5724 | __main__:on_error:37 | Audio service failed to launch (Exception('Mimic was not found. Run install-mimic.sh to install it.')).
2021-10-26 14:31:00.259 | ERROR    |  5724 | mycroft.audio.speech:handle_speak:99 | Error in mute_and_speak
Traceback (most recent call last):
  File "/opt/mycroft-core/mycroft/audio/speech.py", line 95, in handle_speak
    mute_and_speak(chunk, ident, listen)
  File "/opt/mycroft-core/mycroft/audio/speech.py", line 120, in mute_and_speak
    tts.playback.stop()
AttributeError: 'NoneType' object has no attribute 'playback'
2021-10-26 14:31:30.875 | ERROR    |  5724 | mycroft.audio.speech:handle_speak:99 | Error in mute_and_speak
Traceback (most recent call last):
  File "/opt/mycroft-core/mycroft/audio/speech.py", line 95, in handle_speak
    mute_and_speak(chunk, ident, listen)
  File "/opt/mycroft-core/mycroft/audio/speech.py", line 120, in mute_and_speak
    tts.playback.stop()
AttributeError: 'NoneType' object has no attribute 'playback'
2021-10-26 14:31:30.876 | ERROR    |  5724 | mycroft.audio.speech:handle_speak:99 | Error in mute_and_speak
Traceback (most recent call last):
  File "/opt/mycroft-core/mycroft/audio/speech.py", line 95, in handle_speak
    mute_and_speak(chunk, ident, listen)
  File "/opt/mycroft-core/mycroft/audio/speech.py", line 120, in mute_and_speak
    tts.playback.stop()
AttributeError: 'NoneType' object has no attribute 'playback'
2021-10-26 14:31:42.452 | ERROR    |  5724 | websocket | error from callback <bound method MessageBusClient.on_message of <mycroft.messagebus.client.client.MessageBusClient object at 0x7f529673dbd0>>: cannot schedule new futures after interpreter shutdown
2021-10-26 14:31:42.453 | ERROR    |  5724 | websocket | error from callback <bound method MessageBusClient.on_message of <mycroft.messagebus.client.client.MessageBusClient object at 0x7f529673dbd0>>: cannot schedule new futures after interpreter shutdown
2021-10-26 14:31:42.453 | ERROR    |  5724 | websocket | error from callback <bound method MessageBusClient.on_message of <mycroft.messagebus.client.client.MessageBusClient object at 0x7f529673dbd0>>: cannot schedule new futures after interpreter shutdown
2021-10-26 14:31:42.453 | ERROR    |  5724 | websocket | error from callback <bound method MessageBusClient.on_message of <mycroft.messagebus.client.client.MessageBusClient object at 0x7f529673dbd0>>: cannot schedule new futures after interpreter shutdown
2021-10-26 14:31:42.453 | ERROR    |  5724 | websocket | error from callback <bound method MessageBusClient.on_message of <mycroft.messagebus.client.client.MessageBusClient object at 0x7f529673dbd0>>: cannot schedule new futures after interpreter shutdown
2021-10-26 14:31:42.454 | ERROR    |  5724 | websocket | error from callback <bound method MessageBusClient.on_message of <mycroft.messagebus.client.client.MessageBusClient object at 0x7f529673dbd0>>: cannot schedule new futures after interpreter shutdown
2021-10-26 14:31:42.454 | ERROR    |  5724 | websocket | error from callback <bound method MessageBusClient.on_message of <mycroft.messagebus.client.client.MessageBusClient object at 0x7f529673dbd0>>: cannot schedule new futures after interpreter shutdown
2021-10-26 14:31:42.454 | ERROR    |  5724 | websocket | error from callback <bound method MessageBusClient.on_message of <mycroft.messagebus.client.client.MessageBusClient object at 0x7f529673dbd0>>: cannot schedule new futures after interpreter shutdown
2021-10-26 14:31:42.454 | ERROR    |  5724 | websocket | error from callback <bound method MessageBusClient.on_message of <mycroft.messagebus.client.client.MessageBusClient object at 0x7f529673dbd0>>: cannot schedule new futures after interpreter shutdown
2021-10-26 14:31:42.454 | ERROR    |  5724 | websocket | error from callback <bound method MessageBusClient.on_message of <mycroft.messagebus.client.client.MessageBusClient object at 0x7f529673dbd0>>: cannot schedule new futures after interpreter shutdown
2021-10-26 14:31:42.455 | ERROR    |  5724 | websocket | error from callback <bound method MessageBusClient.on_message of <mycroft.messagebus.client.client.MessageBusClient object at 0x7f529673dbd0>>: cannot schedule new futures after interpreter shutdown
2021-10-26 14:31:42.455 | ERROR    |  5724 | websocket | error from callback <bound method MessageBusClient.on_message of <mycroft.messagebus.client.client.MessageBusClient object at 0x7f529673dbd0>>: cannot schedule new futures after interpreter shutdown
2021-10-26 14:31:42.455 | ERROR    |  5724 | websocket | error from callback <bound method MessageBusClient.on_message of <mycroft.messagebus.client.client.MessageBusClient object at 0x7f529673dbd0>>: cannot schedule new futures after interpreter shutdown
2021-10-26 14:31:42.455 | ERROR    |  5724 | websocket | error from callback <bound method MessageBusClient.on_message of <mycroft.messagebus.client.client.MessageBusClient object at 0x7f529673dbd0>>: cannot schedule new futures after interpreter shutdown
2021-10-26 14:31:42.456 | ERROR    |  5724 | websocket | error from callback <bound method MessageBusClient.on_message of <mycroft.messagebus.client.client.MessageBusClient object at 0x7f529673dbd0>>: cannot schedule new futures after interpreter shutdown
2021-10-26 14:31:42.456 | ERROR    |  5724 | websocket | error from callback <bound method MessageBusClient.on_message of <mycroft.messagebus.client.client.MessageBusClient object at 0x7f529673dbd0>>: cannot schedule new futures after interpreter shutdown
2021-10-26 14:31:59.756 | INFO     |  7326 | __main__:main:46 | Starting Audio Service
2021-10-26 14:31:59.757 | INFO     |  7326 | mycroft.messagebus.load_config:load_message_bus_config:33 | Loading message bus configs
2021-10-26 14:31:59.760 | INFO     |  7326 | mycroft_bus_client.client.client | Connected
2021-10-26 14:31:59.761 | INFO     |  7326 | mycroft.util.process_utils:start_message_bus_client:155 | Connected to messagebus
2021-10-26 14:31:59.764 | WARNING  |  7326 | mycroft.tts.tts:clear_cache:428 | This method is deprecated, use TextToSpeechCache.clear
2021-10-26 14:32:00.038 | ERROR    |  7326 | mycroft.tts.mimic_tts:validate_connection:226 | Mimic executable not found
2021-10-26 14:32:00.039 | ERROR    |  7326 | mycroft.tts.tts:create:625 | The TTS could not be loaded.
Traceback (most recent call last):
  File "/opt/mycroft-core/mycroft/tts/mimic_tts.py", line 221, in validate_connection
    subprocess.call([mimic_bin, '--version'])
  File "/opt/hostedtoolcache/Python/3.7.12/x64/lib/python3.7/subprocess.py", line 339, in call
    with Popen(*popenargs, **kwargs) as p:
  File "/opt/hostedtoolcache/Python/3.7.12/x64/lib/python3.7/subprocess.py", line 800, in __init__
    restore_signals, start_new_session)
  File "/opt/hostedtoolcache/Python/3.7.12/x64/lib/python3.7/subprocess.py", line 1465, in _execute_child
    executable = os.fsencode(executable)
  File "/opt/hostedtoolcache/Python/3.7.12/x64/lib/python3.7/os.py", line 812, in fsencode
    filename = fspath(filename)  # Does type-checking of `filename`.
TypeError: expected str, bytes or os.PathLike object, not NoneType

The above exception was the direct cause of the following exception:

Traceback (most recent call last):
  File "/opt/mycroft-core/mycroft/tts/tts.py", line 614, in create
    tts.validator.validate()
  File "/opt/mycroft-core/mycroft/tts/tts.py", line 500, in validate
    self.validate_connection()
  File "/opt/mycroft-core/mycroft/tts/mimic_tts.py", line 229, in validate_connection
    from err
Exception: Mimic was not found. Run install-mimic.sh to install it.
2021-10-26 14:32:00.040 | ERROR    |  7326 | __main__:on_error:37 | Audio service failed to launch (Exception('Mimic was not found. Run install-mimic.sh to install it.')).
2021-10-26 14:32:01.273 | ERROR    |  7326 | mycroft.audio.speech:handle_speak:99 | Error in mute_and_speak
Traceback (most recent call last):
  File "/opt/mycroft-core/mycroft/audio/speech.py", line 95, in handle_speak
    mute_and_speak(chunk, ident, listen)
  File "/opt/mycroft-core/mycroft/audio/speech.py", line 120, in mute_and_speak
    tts.playback.stop()
AttributeError: 'NoneType' object has no attribute 'playback'
2021-10-26 14:32:01.273 | ERROR    |  7326 | mycroft.audio.speech:handle_speak:99 | Error in mute_and_speak
Traceback (most recent call last):
  File "/opt/mycroft-core/mycroft/audio/speech.py", line 95, in handle_speak
    mute_and_speak(chunk, ident, listen)
  File "/opt/mycroft-core/mycroft/audio/speech.py", line 120, in mute_and_speak
    tts.playback.stop()
AttributeError: 'NoneType' object has no attribute 'playback'
2021-10-26 14:32:01.274 | ERROR    |  7326 | mycroft.audio.speech:handle_speak:99 | Error in mute_and_speak
Traceback (most recent call last):
  File "/opt/mycroft-core/mycroft/audio/speech.py", line 95, in handle_speak
    mute_and_speak(chunk, ident, listen)
  File "/opt/mycroft-core/mycroft/audio/speech.py", line 120, in mute_and_speak
    tts.playback.stop()
AttributeError: 'NoneType' object has no attribute 'playback'
2021-10-26 14:32:01.274 | ERROR    |  7326 | mycroft.audio.speech:handle_speak:99 | Error in mute_and_speak
Traceback (most recent call last):
  File "/opt/mycroft-core/mycroft/audio/speech.py", line 95, in handle_speak
    mute_and_speak(chunk, ident, listen)
  File "/opt/mycroft-core/mycroft/audio/speech.py", line 120, in mute_and_speak
    tts.playback.stop()
AttributeError: 'NoneType' object has no attribute 'playback'
2021-10-26 14:32:01.274 | ERROR    |  7326 | mycroft.audio.speech:handle_speak:99 | Error in mute_and_speak
Traceback (most recent call last):
  File "/opt/mycroft-core/mycroft/audio/speech.py", line 95, in handle_speak
    mute_and_speak(chunk, ident, listen)
  File "/opt/mycroft-core/mycroft/audio/speech.py", line 120, in mute_and_speak
    tts.playback.stop()
AttributeError: 'NoneType' object has no attribute 'playback'
2021-10-26 14:32:01.275 | ERROR    |  7326 | mycroft.audio.speech:handle_speak:99 | Error in mute_and_speak
Traceback (most recent call last):
  File "/opt/mycroft-core/mycroft/audio/speech.py", line 95, in handle_speak
    mute_and_speak(chunk, ident, listen)
  File "/opt/mycroft-core/mycroft/audio/speech.py", line 120, in mute_and_speak
    tts.playback.stop()
AttributeError: 'NoneType' object has no attribute 'playback'
2021-10-26 14:32:01.275 | ERROR    |  7326 | mycroft.audio.speech:handle_speak:99 | Error in mute_and_speak
Traceback (most recent call last):
  File "/opt/mycroft-core/mycroft/audio/speech.py", line 95, in handle_speak
    mute_and_speak(chunk, ident, listen)
  File "/opt/mycroft-core/mycroft/audio/speech.py", line 120, in mute_and_speak
    tts.playback.stop()
AttributeError: 'NoneType' object has no attribute 'playback'
2021-10-26 14:32:01.275 | ERROR    |  7326 | mycroft.audio.speech:handle_speak:99 | Error in mute_and_speak
Traceback (most recent call last):
  File "/opt/mycroft-core/mycroft/audio/speech.py", line 95, in handle_speak
    mute_and_speak(chunk, ident, listen)
  File "/opt/mycroft-core/mycroft/audio/speech.py", line 120, in mute_and_speak
    tts.playback.stop()
AttributeError: 'NoneType' object has no attribute 'playback'
2021-10-26 14:32:01.612 | ERROR    |  7326 | mycroft.audio.speech:handle_speak:99 | Error in mute_and_speak
Traceback (most recent call last):
  File "/opt/mycroft-core/mycroft/audio/speech.py", line 95, in handle_speak
    mute_and_speak(chunk, ident, listen)
  File "/opt/mycroft-core/mycroft/audio/speech.py", line 120, in mute_and_speak
    tts.playback.stop()
AttributeError: 'NoneType' object has no attribute 'playback'
2021-10-26 14:32:01.995 | ERROR    |  7326 | mycroft.audio.speech:handle_speak:99 | Error in mute_and_speak
Traceback (most recent call last):
  File "/opt/mycroft-core/mycroft/audio/speech.py", line 95, in handle_speak
    mute_and_speak(chunk, ident, listen)
  File "/opt/mycroft-core/mycroft/audio/speech.py", line 120, in mute_and_speak
    tts.playback.stop()
AttributeError: 'NoneType' object has no attribute 'playback'
2021-10-26 14:32:02.634 | ERROR    |  7326 | mycroft.audio.speech:handle_speak:99 | Error in mute_and_speak
Traceback (most recent call last):
  File "/opt/mycroft-core/mycroft/audio/speech.py", line 95, in handle_speak
    mute_and_speak(chunk, ident, listen)
  File "/opt/mycroft-core/mycroft/audio/speech.py", line 120, in mute_and_speak
    tts.playback.stop()
AttributeError: 'NoneType' object has no attribute 'playback'
2021-10-26 14:32:11.303 | ERROR    |  7326 | mycroft.audio.speech:handle_speak:99 | Error in mute_and_speak
Traceback (most recent call last):
  File "/opt/mycroft-core/mycroft/audio/speech.py", line 95, in handle_speak
    mute_and_speak(chunk, ident, listen)
  File "/opt/mycroft-core/mycroft/audio/speech.py", line 120, in mute_and_speak
    tts.playback.stop()
AttributeError: 'NoneType' object has no attribute 'playback'
2021-10-26 14:32:11.685 | ERROR    |  7326 | mycroft.audio.speech:handle_speak:99 | Error in mute_and_speak
Traceback (most recent call last):
  File "/opt/mycroft-core/mycroft/audio/speech.py", line 95, in handle_speak
    mute_and_speak(chunk, ident, listen)
  File "/opt/mycroft-core/mycroft/audio/speech.py", line 120, in mute_and_speak
    tts.playback.stop()
AttributeError: 'NoneType' object has no attribute 'playback'
2021-10-26 14:32:12.320 | ERROR    |  7326 | mycroft.audio.speech:handle_speak:99 | Error in mute_and_speak
Traceback (most recent call last):
  File "/opt/mycroft-core/mycroft/audio/speech.py", line 95, in handle_speak
    mute_and_speak(chunk, ident, listen)
  File "/opt/mycroft-core/mycroft/audio/speech.py", line 120, in mute_and_speak
    tts.playback.stop()
AttributeError: 'NoneType' object has no attribute 'playback'
2021-10-26 14:32:12.659 | ERROR    |  7326 | mycroft.audio.speech:handle_speak:99 | Error in mute_and_speak
Traceback (most recent call last):
  File "/opt/mycroft-core/mycroft/audio/speech.py", line 95, in handle_speak
    mute_and_speak(chunk, ident, listen)
  File "/opt/mycroft-core/mycroft/audio/speech.py", line 120, in mute_and_speak
    tts.playback.stop()
AttributeError: 'NoneType' object has no attribute 'playback'
2021-10-26 14:32:12.997 | ERROR    |  7326 | mycroft.audio.speech:handle_speak:99 | Error in mute_and_speak
Traceback (most recent call last):
  File "/opt/mycroft-core/mycroft/audio/speech.py", line 95, in handle_speak
    mute_and_speak(chunk, ident, listen)
  File "/opt/mycroft-core/mycroft/audio/speech.py", line 120, in mute_and_speak
    tts.playback.stop()
AttributeError: 'NoneType' object has no attribute 'playback'
2021-10-26 14:32:13.691 | ERROR    |  7326 | mycroft.audio.speech:handle_speak:99 | Error in mute_and_speak
Traceback (most recent call last):
  File "/opt/mycroft-core/mycroft/audio/speech.py", line 95, in handle_speak
    mute_and_speak(chunk, ident, listen)
  File "/opt/mycroft-core/mycroft/audio/speech.py", line 120, in mute_and_speak
    tts.playback.stop()
AttributeError: 'NoneType' object has no attribute 'playback'
2021-10-26 14:32:14.725 | ERROR    |  7326 | mycroft.audio.speech:handle_speak:99 | Error in mute_and_speak
Traceback (most recent call last):
  File "/opt/mycroft-core/mycroft/audio/speech.py", line 95, in handle_speak
    mute_and_speak(chunk, ident, listen)
  File "/opt/mycroft-core/mycroft/audio/speech.py", line 120, in mute_and_speak
    tts.playback.stop()
AttributeError: 'NoneType' object has no attribute 'playback'
2021-10-26 14:32:21.691 | ERROR    |  7326 | mycroft.audio.speech:handle_speak:99 | Error in mute_and_speak
Traceback (most recent call last):
  File "/opt/mycroft-core/mycroft/audio/speech.py", line 95, in handle_speak
    mute_and_speak(chunk, ident, listen)
  File "/opt/mycroft-core/mycroft/audio/speech.py", line 120, in mute_and_speak
    tts.playback.stop()
AttributeError: 'NoneType' object has no attribute 'playback'
2021-10-26 14:32:22.403 | ERROR    |  7326 | mycroft.audio.speech:handle_speak:99 | Error in mute_and_speak
Traceback (most recent call last):
  File "/opt/mycroft-core/mycroft/audio/speech.py", line 95, in handle_speak
    mute_and_speak(chunk, ident, listen)
  File "/opt/mycroft-core/mycroft/audio/speech.py", line 120, in mute_and_speak
    tts.playback.stop()
AttributeError: 'NoneType' object has no attribute 'playback'
2021-10-26 14:32:22.730 | ERROR    |  7326 | mycroft.audio.speech:handle_speak:99 | Error in mute_and_speak
Traceback (most recent call last):
  File "/opt/mycroft-core/mycroft/audio/speech.py", line 95, in handle_speak
    mute_and_speak(chunk, ident, listen)
  File "/opt/mycroft-core/mycroft/audio/speech.py", line 120, in mute_and_speak
    tts.playback.stop()
AttributeError: 'NoneType' object has no attribute 'playback'
Exception ignored in: <module 'threading' from '/opt/hostedtoolcache/Python/3.7.12/x64/lib/python3.7/threading.py'>
Traceback (most recent call last):
  File "/opt/hostedtoolcache/Python/3.7.12/x64/lib/python3.7/threading.py", line 1307, in _shutdown
    lock.acquire()
KeyboardInterrupt
