2021-10-15 17:05:29.370 | INFO     |  5358 | __main__:main:50 | Starting message bus service...
2021-10-15 17:05:29.378 | INFO     |  5358 | mycroft.messagebus.load_config:load_message_bus_config:33 | Loading message bus configs
2021-10-15 17:05:29.387 | INFO     |  5358 | __main__:on_ready:37 | Message bus service started!
2021-10-15 17:05:29.393 | INFO     |  5358 | tornado.access | 101 GET /core (127.0.0.1) 0.70ms
2021-10-15 17:05:29.468 | INFO     |  5358 | tornado.access | 101 GET /core (127.0.0.1) 0.44ms
2021-10-15 17:05:29.479 | INFO     |  5358 | tornado.access | 101 GET /core (127.0.0.1) 0.45ms
2021-10-15 17:05:29.577 | INFO     |  5358 | tornado.access | 101 GET /core (127.0.0.1) 0.63ms
2021-10-15 17:05:34.336 | INFO     |  5358 | tornado.access | 101 GET /core (127.0.0.1) 0.58ms
2021-10-15 17:06:27.622 | ERROR    |  5358 | tornado.application | Uncaught exception GET /core (127.0.0.1)
HTTPServerRequest(protocol='http', host='0.0.0.0:8181', method='GET', uri='/core', version='HTTP/1.1', remote_ip='127.0.0.1')
Traceback (most recent call last):
  File "/opt/mycroft-core/.venv/lib/python3.7/site-packages/tornado/websocket.py", line 649, in _run_callback
    result = callback(*args, **kwargs)
  File "/opt/mycroft-core/mycroft/messagebus/service/event_handler.py", line 53, in on_message
    client.write_message(message)
  File "/opt/mycroft-core/.venv/lib/python3.7/site-packages/tornado/websocket.py", line 339, in write_message
    raise WebSocketClosedError()
tornado.websocket.WebSocketClosedError
2021-10-15 17:06:27.672 | ERROR    |  5358 | asyncio | Task exception was never retrieved
future: <Task finished coro=<WebSocketProtocol13.write_message.<locals>.wrapper() done, defined at /opt/mycroft-core/.venv/lib/python3.7/site-packages/tornado/websocket.py:1102> exception=WebSocketClosedError()>
Traceback (most recent call last):
  File "/opt/mycroft-core/.venv/lib/python3.7/site-packages/tornado/websocket.py", line 1104, in wrapper
    await fut
tornado.iostream.StreamClosedError: Stream is closed

During handling of the above exception, another exception occurred:

Traceback (most recent call last):
  File "/opt/mycroft-core/.venv/lib/python3.7/site-packages/tornado/websocket.py", line 1106, in wrapper
    raise WebSocketClosedError()
tornado.websocket.WebSocketClosedError
2021-10-15 17:06:32.676 | INFO     |  5358 | tornado.access | 101 GET /core (127.0.0.1) 0.56ms
2021-10-15 17:06:40.433 | INFO     |  5358 | tornado.access | 101 GET /core (127.0.0.1) 0.52ms
2021-10-15 17:06:40.464 | INFO     |  5358 | tornado.access | 101 GET /core (127.0.0.1) 0.54ms
2021-10-15 17:08:53.298 | INFO     |  5358 | __main__:on_stopping:45 | Message bus is shutting down...
