2021-10-29 13:58:20.691 | INFO     |  5338 | __main__:main:46 | Starting Audio Service
2021-10-29 13:58:20.692 | INFO     |  5338 | mycroft.messagebus.load_config:load_message_bus_config:33 | Loading message bus configs
2021-10-29 13:58:20.695 | INFO     |  5338 | mycroft_bus_client.client.client | Connected
2021-10-29 13:58:20.702 | INFO     |  5338 | mycroft.util.process_utils:start_message_bus_client:155 | Connected to messagebus
2021-10-29 13:58:20.712 | WARNING  |  5338 | mycroft.tts.tts:clear_cache:428 | This method is deprecated, use TextToSpeechCache.clear
2021-10-29 13:58:20.884 | ERROR    |  5338 | mycroft.tts.mimic_tts:validate_connection:226 | Mimic executable not found
2021-10-29 13:58:20.884 | ERROR    |  5338 | mycroft.tts.tts:create:625 | The TTS could not be loaded.
Traceback (most recent call last):
  File "/opt/mycroft-core/mycroft/tts/mimic_tts.py", line 221, in validate_connection
    subprocess.call([mimic_bin, '--version'])
  File "/opt/hostedtoolcache/Python/3.7.12/x64/lib/python3.7/subprocess.py", line 339, in call
    with Popen(*popenargs, **kwargs) as p:
  File "/opt/hostedtoolcache/Python/3.7.12/x64/lib/python3.7/subprocess.py", line 800, in __init__
    restore_signals, start_new_session)
  File "/opt/hostedtoolcache/Python/3.7.12/x64/lib/python3.7/subprocess.py", line 1465, in _execute_child
    executable = os.fsencode(executable)
  File "/opt/hostedtoolcache/Python/3.7.12/x64/lib/python3.7/os.py", line 812, in fsencode
    filename = fspath(filename)  # Does type-checking of `filename`.
TypeError: expected str, bytes or os.PathLike object, not NoneType

The above exception was the direct cause of the following exception:

Traceback (most recent call last):
  File "/opt/mycroft-core/mycroft/tts/tts.py", line 614, in create
    tts.validator.validate()
  File "/opt/mycroft-core/mycroft/tts/tts.py", line 500, in validate
    self.validate_connection()
  File "/opt/mycroft-core/mycroft/tts/mimic_tts.py", line 229, in validate_connection
    from err
Exception: Mimic was not found. Run install-mimic.sh to install it.
2021-10-29 13:58:20.923 | ERROR    |  5338 | __main__:on_error:37 | Audio service failed to launch (Exception('Mimic was not found. Run install-mimic.sh to install it.')).
2021-10-29 13:58:30.813 | ERROR    |  5338 | mycroft.audio.speech:handle_speak:99 | Error in mute_and_speak
Traceback (most recent call last):
  File "/opt/mycroft-core/mycroft/audio/speech.py", line 95, in handle_speak
    mute_and_speak(chunk, ident, listen)
  File "/opt/mycroft-core/mycroft/audio/speech.py", line 120, in mute_and_speak
    tts.playback.stop()
AttributeError: 'NoneType' object has no attribute 'playback'
2021-10-29 13:59:01.362 | ERROR    |  5338 | mycroft.audio.speech:handle_speak:99 | Error in mute_and_speak
Traceback (most recent call last):
  File "/opt/mycroft-core/mycroft/audio/speech.py", line 95, in handle_speak
    mute_and_speak(chunk, ident, listen)
  File "/opt/mycroft-core/mycroft/audio/speech.py", line 120, in mute_and_speak
    tts.playback.stop()
AttributeError: 'NoneType' object has no attribute 'playback'
2021-10-29 13:59:01.363 | ERROR    |  5338 | mycroft.audio.speech:handle_speak:99 | Error in mute_and_speak
Traceback (most recent call last):
  File "/opt/mycroft-core/mycroft/audio/speech.py", line 95, in handle_speak
    mute_and_speak(chunk, ident, listen)
  File "/opt/mycroft-core/mycroft/audio/speech.py", line 120, in mute_and_speak
    tts.playback.stop()
AttributeError: 'NoneType' object has no attribute 'playback'
2021-10-29 13:59:31.730 | ERROR    |  5338 | mycroft.audio.speech:handle_speak:99 | Error in mute_and_speak
Traceback (most recent call last):
  File "/opt/mycroft-core/mycroft/audio/speech.py", line 95, in handle_speak
    mute_and_speak(chunk, ident, listen)
  File "/opt/mycroft-core/mycroft/audio/speech.py", line 120, in mute_and_speak
    tts.playback.stop()
AttributeError: 'NoneType' object has no attribute 'playback'
2021-10-29 13:59:31.731 | ERROR    |  5338 | mycroft.audio.speech:handle_speak:99 | Error in mute_and_speak
Traceback (most recent call last):
  File "/opt/mycroft-core/mycroft/audio/speech.py", line 95, in handle_speak
    mute_and_speak(chunk, ident, listen)
  File "/opt/mycroft-core/mycroft/audio/speech.py", line 120, in mute_and_speak
    tts.playback.stop()
AttributeError: 'NoneType' object has no attribute 'playback'
2021-10-29 13:59:31.731 | ERROR    |  5338 | mycroft.audio.speech:handle_speak:99 | Error in mute_and_speak
Traceback (most recent call last):
  File "/opt/mycroft-core/mycroft/audio/speech.py", line 95, in handle_speak
    mute_and_speak(chunk, ident, listen)
  File "/opt/mycroft-core/mycroft/audio/speech.py", line 120, in mute_and_speak
    tts.playback.stop()
AttributeError: 'NoneType' object has no attribute 'playback'
2021-10-29 13:59:31.732 | ERROR    |  5338 | mycroft.audio.speech:handle_speak:99 | Error in mute_and_speak
Traceback (most recent call last):
  File "/opt/mycroft-core/mycroft/audio/speech.py", line 95, in handle_speak
    mute_and_speak(chunk, ident, listen)
  File "/opt/mycroft-core/mycroft/audio/speech.py", line 120, in mute_and_speak
    tts.playback.stop()
AttributeError: 'NoneType' object has no attribute 'playback'
2021-10-29 13:59:31.733 | ERROR    |  5338 | mycroft.audio.speech:handle_speak:99 | Error in mute_and_speak
Traceback (most recent call last):
  File "/opt/mycroft-core/mycroft/audio/speech.py", line 95, in handle_speak
    mute_and_speak(chunk, ident, listen)
  File "/opt/mycroft-core/mycroft/audio/speech.py", line 120, in mute_and_speak
    tts.playback.stop()
AttributeError: 'NoneType' object has no attribute 'playback'
2021-10-29 13:59:31.733 | ERROR    |  5338 | mycroft.audio.speech:handle_speak:99 | Error in mute_and_speak
Traceback (most recent call last):
  File "/opt/mycroft-core/mycroft/audio/speech.py", line 95, in handle_speak
    mute_and_speak(chunk, ident, listen)
  File "/opt/mycroft-core/mycroft/audio/speech.py", line 120, in mute_and_speak
    tts.playback.stop()
AttributeError: 'NoneType' object has no attribute 'playback'
2021-10-29 13:59:31.734 | ERROR    |  5338 | mycroft.audio.speech:handle_speak:99 | Error in mute_and_speak
Traceback (most recent call last):
  File "/opt/mycroft-core/mycroft/audio/speech.py", line 95, in handle_speak
    mute_and_speak(chunk, ident, listen)
  File "/opt/mycroft-core/mycroft/audio/speech.py", line 120, in mute_and_speak
    tts.playback.stop()
AttributeError: 'NoneType' object has no attribute 'playback'
2021-10-29 13:59:36.717 | ERROR    |  5338 | websocket | error from callback <bound method MessageBusClient.on_message of <mycroft.messagebus.client.client.MessageBusClient object at 0x7f4741651450>>: cannot schedule new futures after shutdown
2021-10-29 13:59:36.722 | ERROR    |  5338 | mycroft_bus_client.client.client | === RuntimeError('cannot schedule new futures after shutdown') ===
Traceback (most recent call last):
  File "/opt/mycroft-core/.venv/lib/python3.7/site-packages/websocket/_app.py", line 407, in _callback
    callback(self, *args)
  File "/opt/mycroft-core/.venv/lib/python3.7/site-packages/mycroft_bus_client/client/client.py", line 182, in on_message
    self.emitter.emit('message', message)
  File "/opt/mycroft-core/.venv/lib/python3.7/site-packages/pyee/_base.py", line 113, in emit
    handled = self._call_handlers(event, args, kwargs)
  File "/opt/mycroft-core/.venv/lib/python3.7/site-packages/pyee/_base.py", line 96, in _call_handlers
    self._emit_run(f, args, kwargs)
  File "/opt/mycroft-core/.venv/lib/python3.7/site-packages/pyee/_executor.py", line 50, in _emit_run
    future = self._executor.submit(f, *args, **kwargs)
  File "/opt/hostedtoolcache/Python/3.7.12/x64/lib/python3.7/concurrent/futures/thread.py", line 163, in submit
    raise RuntimeError('cannot schedule new futures after shutdown')
RuntimeError: cannot schedule new futures after shutdown
2021-10-29 13:59:36.724 | ERROR    |  5338 | mycroft_bus_client.client.client | Exception closing websocket: RuntimeError('cannot schedule new futures after shutdown')
2021-10-29 13:59:36.724 | WARNING  |  5338 | mycroft_bus_client.client.client | Message Bus Client will reconnect in 5.0 seconds.
2021-10-29 13:59:49.622 | INFO     |  6955 | __main__:main:46 | Starting Audio Service
2021-10-29 13:59:49.624 | INFO     |  6955 | mycroft.messagebus.load_config:load_message_bus_config:33 | Loading message bus configs
2021-10-29 13:59:49.629 | INFO     |  6955 | mycroft_bus_client.client.client | Connected
2021-10-29 13:59:49.633 | INFO     |  6955 | mycroft.util.process_utils:start_message_bus_client:155 | Connected to messagebus
2021-10-29 13:59:49.636 | WARNING  |  6955 | mycroft.tts.tts:clear_cache:428 | This method is deprecated, use TextToSpeechCache.clear
2021-10-29 13:59:49.709 | ERROR    |  6955 | mycroft.tts.mimic_tts:validate_connection:226 | Mimic executable not found
2021-10-29 13:59:49.709 | ERROR    |  6955 | mycroft.tts.tts:create:625 | The TTS could not be loaded.
Traceback (most recent call last):
  File "/opt/mycroft-core/mycroft/tts/mimic_tts.py", line 221, in validate_connection
    subprocess.call([mimic_bin, '--version'])
  File "/opt/hostedtoolcache/Python/3.7.12/x64/lib/python3.7/subprocess.py", line 339, in call
    with Popen(*popenargs, **kwargs) as p:
  File "/opt/hostedtoolcache/Python/3.7.12/x64/lib/python3.7/subprocess.py", line 800, in __init__
    restore_signals, start_new_session)
  File "/opt/hostedtoolcache/Python/3.7.12/x64/lib/python3.7/subprocess.py", line 1465, in _execute_child
    executable = os.fsencode(executable)
  File "/opt/hostedtoolcache/Python/3.7.12/x64/lib/python3.7/os.py", line 812, in fsencode
    filename = fspath(filename)  # Does type-checking of `filename`.
TypeError: expected str, bytes or os.PathLike object, not NoneType

The above exception was the direct cause of the following exception:

Traceback (most recent call last):
  File "/opt/mycroft-core/mycroft/tts/tts.py", line 614, in create
    tts.validator.validate()
  File "/opt/mycroft-core/mycroft/tts/tts.py", line 500, in validate
    self.validate_connection()
  File "/opt/mycroft-core/mycroft/tts/mimic_tts.py", line 229, in validate_connection
    from err
Exception: Mimic was not found. Run install-mimic.sh to install it.
2021-10-29 13:59:49.711 | ERROR    |  6955 | __main__:on_error:37 | Audio service failed to launch (Exception('Mimic was not found. Run install-mimic.sh to install it.')).
2021-10-29 13:59:51.242 | ERROR    |  6955 | mycroft.audio.speech:handle_speak:99 | Error in mute_and_speak
Traceback (most recent call last):
  File "/opt/mycroft-core/mycroft/audio/speech.py", line 95, in handle_speak
    mute_and_speak(chunk, ident, listen)
  File "/opt/mycroft-core/mycroft/audio/speech.py", line 120, in mute_and_speak
    tts.playback.stop()
AttributeError: 'NoneType' object has no attribute 'playback'
2021-10-29 13:59:51.636 | ERROR    |  6955 | mycroft.audio.speech:handle_speak:99 | Error in mute_and_speak
Traceback (most recent call last):
  File "/opt/mycroft-core/mycroft/audio/speech.py", line 95, in handle_speak
    mute_and_speak(chunk, ident, listen)
  File "/opt/mycroft-core/mycroft/audio/speech.py", line 120, in mute_and_speak
    tts.playback.stop()
AttributeError: 'NoneType' object has no attribute 'playback'
2021-10-29 13:59:52.037 | ERROR    |  6955 | mycroft.audio.speech:handle_speak:99 | Error in mute_and_speak
Traceback (most recent call last):
  File "/opt/mycroft-core/mycroft/audio/speech.py", line 95, in handle_speak
    mute_and_speak(chunk, ident, listen)
  File "/opt/mycroft-core/mycroft/audio/speech.py", line 120, in mute_and_speak
    tts.playback.stop()
AttributeError: 'NoneType' object has no attribute 'playback'
2021-10-29 13:59:52.432 | ERROR    |  6955 | mycroft.audio.speech:handle_speak:99 | Error in mute_and_speak
Traceback (most recent call last):
  File "/opt/mycroft-core/mycroft/audio/speech.py", line 95, in handle_speak
    mute_and_speak(chunk, ident, listen)
  File "/opt/mycroft-core/mycroft/audio/speech.py", line 120, in mute_and_speak
    tts.playback.stop()
AttributeError: 'NoneType' object has no attribute 'playback'
2021-10-29 13:59:53.072 | ERROR    |  6955 | mycroft.audio.speech:handle_speak:99 | Error in mute_and_speak
Traceback (most recent call last):
  File "/opt/mycroft-core/mycroft/audio/speech.py", line 95, in handle_speak
    mute_and_speak(chunk, ident, listen)
  File "/opt/mycroft-core/mycroft/audio/speech.py", line 120, in mute_and_speak
    tts.playback.stop()
AttributeError: 'NoneType' object has no attribute 'playback'
2021-10-29 14:00:01.279 | ERROR    |  6955 | mycroft.audio.speech:handle_speak:99 | Error in mute_and_speak
Traceback (most recent call last):
  File "/opt/mycroft-core/mycroft/audio/speech.py", line 95, in handle_speak
    mute_and_speak(chunk, ident, listen)
  File "/opt/mycroft-core/mycroft/audio/speech.py", line 120, in mute_and_speak
    tts.playback.stop()
AttributeError: 'NoneType' object has no attribute 'playback'
2021-10-29 14:00:01.702 | ERROR    |  6955 | mycroft.audio.speech:handle_speak:99 | Error in mute_and_speak
Traceback (most recent call last):
  File "/opt/mycroft-core/mycroft/audio/speech.py", line 95, in handle_speak
    mute_and_speak(chunk, ident, listen)
  File "/opt/mycroft-core/mycroft/audio/speech.py", line 120, in mute_and_speak
    tts.playback.stop()
AttributeError: 'NoneType' object has no attribute 'playback'
2021-10-29 14:00:02.090 | ERROR    |  6955 | mycroft.audio.speech:handle_speak:99 | Error in mute_and_speak
Traceback (most recent call last):
  File "/opt/mycroft-core/mycroft/audio/speech.py", line 95, in handle_speak
    mute_and_speak(chunk, ident, listen)
  File "/opt/mycroft-core/mycroft/audio/speech.py", line 120, in mute_and_speak
    tts.playback.stop()
AttributeError: 'NoneType' object has no attribute 'playback'
2021-10-29 14:00:02.461 | ERROR    |  6955 | mycroft.audio.speech:handle_speak:99 | Error in mute_and_speak
Traceback (most recent call last):
  File "/opt/mycroft-core/mycroft/audio/speech.py", line 95, in handle_speak
    mute_and_speak(chunk, ident, listen)
  File "/opt/mycroft-core/mycroft/audio/speech.py", line 120, in mute_and_speak
    tts.playback.stop()
AttributeError: 'NoneType' object has no attribute 'playback'
2021-10-29 14:00:02.802 | ERROR    |  6955 | mycroft.audio.speech:handle_speak:99 | Error in mute_and_speak
Traceback (most recent call last):
  File "/opt/mycroft-core/mycroft/audio/speech.py", line 95, in handle_speak
    mute_and_speak(chunk, ident, listen)
  File "/opt/mycroft-core/mycroft/audio/speech.py", line 120, in mute_and_speak
    tts.playback.stop()
AttributeError: 'NoneType' object has no attribute 'playback'
2021-10-29 14:00:03.431 | ERROR    |  6955 | mycroft.audio.speech:handle_speak:99 | Error in mute_and_speak
Traceback (most recent call last):
  File "/opt/mycroft-core/mycroft/audio/speech.py", line 95, in handle_speak
    mute_and_speak(chunk, ident, listen)
  File "/opt/mycroft-core/mycroft/audio/speech.py", line 120, in mute_and_speak
    tts.playback.stop()
AttributeError: 'NoneType' object has no attribute 'playback'
2021-10-29 14:00:04.134 | ERROR    |  6955 | mycroft.audio.speech:handle_speak:99 | Error in mute_and_speak
Traceback (most recent call last):
  File "/opt/mycroft-core/mycroft/audio/speech.py", line 95, in handle_speak
    mute_and_speak(chunk, ident, listen)
  File "/opt/mycroft-core/mycroft/audio/speech.py", line 120, in mute_and_speak
    tts.playback.stop()
AttributeError: 'NoneType' object has no attribute 'playback'
2021-10-29 14:00:05.216 | ERROR    |  6955 | mycroft.audio.speech:handle_speak:99 | Error in mute_and_speak
Traceback (most recent call last):
  File "/opt/mycroft-core/mycroft/audio/speech.py", line 95, in handle_speak
    mute_and_speak(chunk, ident, listen)
  File "/opt/mycroft-core/mycroft/audio/speech.py", line 120, in mute_and_speak
    tts.playback.stop()
AttributeError: 'NoneType' object has no attribute 'playback'
2021-10-29 14:00:11.626 | ERROR    |  6955 | mycroft.audio.speech:handle_speak:99 | Error in mute_and_speak
Traceback (most recent call last):
  File "/opt/mycroft-core/mycroft/audio/speech.py", line 95, in handle_speak
    mute_and_speak(chunk, ident, listen)
  File "/opt/mycroft-core/mycroft/audio/speech.py", line 120, in mute_and_speak
    tts.playback.stop()
AttributeError: 'NoneType' object has no attribute 'playback'
Exception ignored in: <module 'threading' from '/opt/hostedtoolcache/Python/3.7.12/x64/lib/python3.7/threading.py'>
Traceback (most recent call last):
  File "/opt/hostedtoolcache/Python/3.7.12/x64/lib/python3.7/threading.py", line 1307, in _shutdown
    lock.acquire()
KeyboardInterrupt
