2021-10-23 09:29:58.472 | INFO     |  5663 | __main__:main:46 | Starting Audio Service
2021-10-23 09:29:58.473 | INFO     |  5663 | mycroft.messagebus.load_config:load_message_bus_config:33 | Loading message bus configs
2021-10-23 09:29:58.475 | INFO     |  5663 | mycroft_bus_client.client.client | Connected
2021-10-23 09:29:58.476 | INFO     |  5663 | mycroft.util.process_utils:start_message_bus_client:155 | Connected to messagebus
2021-10-23 09:29:58.479 | WARNING  |  5663 | mycroft.tts.tts:clear_cache:428 | This method is deprecated, use TextToSpeechCache.clear
2021-10-23 09:29:58.829 | ERROR    |  5663 | mycroft.tts.mimic_tts:validate_connection:226 | Mimic executable not found
2021-10-23 09:29:58.830 | ERROR    |  5663 | mycroft.tts.tts:create:625 | The TTS could not be loaded.
Traceback (most recent call last):
  File "/opt/mycroft-core/mycroft/tts/mimic_tts.py", line 221, in validate_connection
    subprocess.call([mimic_bin, '--version'])
  File "/opt/hostedtoolcache/Python/3.7.12/x64/lib/python3.7/subprocess.py", line 339, in call
    with Popen(*popenargs, **kwargs) as p:
  File "/opt/hostedtoolcache/Python/3.7.12/x64/lib/python3.7/subprocess.py", line 800, in __init__
    restore_signals, start_new_session)
  File "/opt/hostedtoolcache/Python/3.7.12/x64/lib/python3.7/subprocess.py", line 1465, in _execute_child
    executable = os.fsencode(executable)
  File "/opt/hostedtoolcache/Python/3.7.12/x64/lib/python3.7/os.py", line 812, in fsencode
    filename = fspath(filename)  # Does type-checking of `filename`.
TypeError: expected str, bytes or os.PathLike object, not NoneType

The above exception was the direct cause of the following exception:

Traceback (most recent call last):
  File "/opt/mycroft-core/mycroft/tts/tts.py", line 614, in create
    tts.validator.validate()
  File "/opt/mycroft-core/mycroft/tts/tts.py", line 500, in validate
    self.validate_connection()
  File "/opt/mycroft-core/mycroft/tts/mimic_tts.py", line 229, in validate_connection
    from err
Exception: Mimic was not found. Run install-mimic.sh to install it.
2021-10-23 09:29:58.845 | ERROR    |  5663 | __main__:on_error:37 | Audio service failed to launch (Exception('Mimic was not found. Run install-mimic.sh to install it.')).
2021-10-23 09:30:16.043 | ERROR    |  5663 | mycroft.audio.speech:handle_speak:99 | Error in mute_and_speak
Traceback (most recent call last):
  File "/opt/mycroft-core/mycroft/audio/speech.py", line 95, in handle_speak
    mute_and_speak(chunk, ident, listen)
  File "/opt/mycroft-core/mycroft/audio/speech.py", line 120, in mute_and_speak
    tts.playback.stop()
AttributeError: 'NoneType' object has no attribute 'playback'
2021-10-23 09:30:46.653 | ERROR    |  5663 | mycroft.audio.speech:handle_speak:99 | Error in mute_and_speak
Traceback (most recent call last):
  File "/opt/mycroft-core/mycroft/audio/speech.py", line 95, in handle_speak
    mute_and_speak(chunk, ident, listen)
  File "/opt/mycroft-core/mycroft/audio/speech.py", line 120, in mute_and_speak
    tts.playback.stop()
AttributeError: 'NoneType' object has no attribute 'playback'
2021-10-23 09:30:46.654 | ERROR    |  5663 | mycroft.audio.speech:handle_speak:99 | Error in mute_and_speak
Traceback (most recent call last):
  File "/opt/mycroft-core/mycroft/audio/speech.py", line 95, in handle_speak
    mute_and_speak(chunk, ident, listen)
  File "/opt/mycroft-core/mycroft/audio/speech.py", line 120, in mute_and_speak
    tts.playback.stop()
AttributeError: 'NoneType' object has no attribute 'playback'
2021-10-23 09:31:02.491 | ERROR    |  5663 | websocket | error from callback <bound method MessageBusClient.on_message of <mycroft.messagebus.client.client.MessageBusClient object at 0x7f13744d9710>>: cannot schedule new futures after shutdown
2021-10-23 09:31:02.492 | ERROR    |  5663 | websocket | error from callback <bound method MessageBusClient.on_message of <mycroft.messagebus.client.client.MessageBusClient object at 0x7f13744d9710>>: cannot schedule new futures after shutdown
2021-10-23 09:31:02.492 | ERROR    |  5663 | websocket | error from callback <bound method MessageBusClient.on_message of <mycroft.messagebus.client.client.MessageBusClient object at 0x7f13744d9710>>: cannot schedule new futures after shutdown
2021-10-23 09:31:02.492 | ERROR    |  5663 | websocket | error from callback <bound method MessageBusClient.on_message of <mycroft.messagebus.client.client.MessageBusClient object at 0x7f13744d9710>>: cannot schedule new futures after shutdown
2021-10-23 09:31:02.493 | ERROR    |  5663 | websocket | error from callback <bound method MessageBusClient.on_message of <mycroft.messagebus.client.client.MessageBusClient object at 0x7f13744d9710>>: cannot schedule new futures after shutdown
2021-10-23 09:31:02.493 | ERROR    |  5663 | websocket | error from callback <bound method MessageBusClient.on_message of <mycroft.messagebus.client.client.MessageBusClient object at 0x7f13744d9710>>: cannot schedule new futures after shutdown
2021-10-23 09:31:02.493 | ERROR    |  5663 | websocket | error from callback <bound method MessageBusClient.on_message of <mycroft.messagebus.client.client.MessageBusClient object at 0x7f13744d9710>>: cannot schedule new futures after shutdown
2021-10-23 09:31:02.493 | ERROR    |  5663 | websocket | error from callback <bound method MessageBusClient.on_message of <mycroft.messagebus.client.client.MessageBusClient object at 0x7f13744d9710>>: cannot schedule new futures after shutdown
2021-10-23 09:31:02.493 | ERROR    |  5663 | websocket | error from callback <bound method MessageBusClient.on_message of <mycroft.messagebus.client.client.MessageBusClient object at 0x7f13744d9710>>: cannot schedule new futures after shutdown
2021-10-23 09:31:02.493 | ERROR    |  5663 | websocket | error from callback <bound method MessageBusClient.on_message of <mycroft.messagebus.client.client.MessageBusClient object at 0x7f13744d9710>>: cannot schedule new futures after shutdown
2021-10-23 09:31:02.494 | ERROR    |  5663 | websocket | error from callback <bound method MessageBusClient.on_message of <mycroft.messagebus.client.client.MessageBusClient object at 0x7f13744d9710>>: cannot schedule new futures after shutdown
2021-10-23 09:31:13.582 | INFO     |  7265 | __main__:main:46 | Starting Audio Service
2021-10-23 09:31:13.583 | INFO     |  7265 | mycroft.messagebus.load_config:load_message_bus_config:33 | Loading message bus configs
2021-10-23 09:31:13.585 | INFO     |  7265 | mycroft_bus_client.client.client | Connected
2021-10-23 09:31:13.586 | INFO     |  7265 | mycroft.util.process_utils:start_message_bus_client:155 | Connected to messagebus
2021-10-23 09:31:13.589 | WARNING  |  7265 | mycroft.tts.tts:clear_cache:428 | This method is deprecated, use TextToSpeechCache.clear
2021-10-23 09:31:13.858 | ERROR    |  7265 | mycroft.tts.mimic_tts:validate_connection:226 | Mimic executable not found
2021-10-23 09:31:13.859 | ERROR    |  7265 | mycroft.tts.tts:create:625 | The TTS could not be loaded.
Traceback (most recent call last):
  File "/opt/mycroft-core/mycroft/tts/mimic_tts.py", line 221, in validate_connection
    subprocess.call([mimic_bin, '--version'])
  File "/opt/hostedtoolcache/Python/3.7.12/x64/lib/python3.7/subprocess.py", line 339, in call
    with Popen(*popenargs, **kwargs) as p:
  File "/opt/hostedtoolcache/Python/3.7.12/x64/lib/python3.7/subprocess.py", line 800, in __init__
    restore_signals, start_new_session)
  File "/opt/hostedtoolcache/Python/3.7.12/x64/lib/python3.7/subprocess.py", line 1465, in _execute_child
    executable = os.fsencode(executable)
  File "/opt/hostedtoolcache/Python/3.7.12/x64/lib/python3.7/os.py", line 812, in fsencode
    filename = fspath(filename)  # Does type-checking of `filename`.
TypeError: expected str, bytes or os.PathLike object, not NoneType

The above exception was the direct cause of the following exception:

Traceback (most recent call last):
  File "/opt/mycroft-core/mycroft/tts/tts.py", line 614, in create
    tts.validator.validate()
  File "/opt/mycroft-core/mycroft/tts/tts.py", line 500, in validate
    self.validate_connection()
  File "/opt/mycroft-core/mycroft/tts/mimic_tts.py", line 229, in validate_connection
    from err
Exception: Mimic was not found. Run install-mimic.sh to install it.
2021-10-23 09:31:13.860 | ERROR    |  7265 | __main__:on_error:37 | Audio service failed to launch (Exception('Mimic was not found. Run install-mimic.sh to install it.')).
2021-10-23 09:31:15.208 | ERROR    |  7265 | mycroft.audio.speech:handle_speak:99 | Error in mute_and_speak
Traceback (most recent call last):
  File "/opt/mycroft-core/mycroft/audio/speech.py", line 95, in handle_speak
    mute_and_speak(chunk, ident, listen)
  File "/opt/mycroft-core/mycroft/audio/speech.py", line 120, in mute_and_speak
    tts.playback.stop()
AttributeError: 'NoneType' object has no attribute 'playback'
2021-10-23 09:31:15.549 | ERROR    |  7265 | mycroft.audio.speech:handle_speak:99 | Error in mute_and_speak
Traceback (most recent call last):
  File "/opt/mycroft-core/mycroft/audio/speech.py", line 95, in handle_speak
    mute_and_speak(chunk, ident, listen)
  File "/opt/mycroft-core/mycroft/audio/speech.py", line 120, in mute_and_speak
    tts.playback.stop()
AttributeError: 'NoneType' object has no attribute 'playback'
2021-10-23 09:31:15.892 | ERROR    |  7265 | mycroft.audio.speech:handle_speak:99 | Error in mute_and_speak
Traceback (most recent call last):
  File "/opt/mycroft-core/mycroft/audio/speech.py", line 95, in handle_speak
    mute_and_speak(chunk, ident, listen)
  File "/opt/mycroft-core/mycroft/audio/speech.py", line 120, in mute_and_speak
    tts.playback.stop()
AttributeError: 'NoneType' object has no attribute 'playback'
2021-10-23 09:31:16.570 | ERROR    |  7265 | mycroft.audio.speech:handle_speak:99 | Error in mute_and_speak
Traceback (most recent call last):
  File "/opt/mycroft-core/mycroft/audio/speech.py", line 95, in handle_speak
    mute_and_speak(chunk, ident, listen)
  File "/opt/mycroft-core/mycroft/audio/speech.py", line 120, in mute_and_speak
    tts.playback.stop()
AttributeError: 'NoneType' object has no attribute 'playback'
2021-10-23 09:31:17.580 | ERROR    |  7265 | mycroft.audio.speech:handle_speak:99 | Error in mute_and_speak
Traceback (most recent call last):
  File "/opt/mycroft-core/mycroft/audio/speech.py", line 95, in handle_speak
    mute_and_speak(chunk, ident, listen)
  File "/opt/mycroft-core/mycroft/audio/speech.py", line 120, in mute_and_speak
    tts.playback.stop()
AttributeError: 'NoneType' object has no attribute 'playback'
2021-10-23 09:31:17.581 | ERROR    |  7265 | mycroft.audio.speech:handle_speak:99 | Error in mute_and_speak
Traceback (most recent call last):
  File "/opt/mycroft-core/mycroft/audio/speech.py", line 95, in handle_speak
    mute_and_speak(chunk, ident, listen)
  File "/opt/mycroft-core/mycroft/audio/speech.py", line 120, in mute_and_speak
    tts.playback.stop()
AttributeError: 'NoneType' object has no attribute 'playback'
2021-10-23 09:31:17.581 | ERROR    |  7265 | mycroft.audio.speech:handle_speak:99 | Error in mute_and_speak
Traceback (most recent call last):
  File "/opt/mycroft-core/mycroft/audio/speech.py", line 95, in handle_speak
    mute_and_speak(chunk, ident, listen)
  File "/opt/mycroft-core/mycroft/audio/speech.py", line 120, in mute_and_speak
    tts.playback.stop()
AttributeError: 'NoneType' object has no attribute 'playback'
2021-10-23 09:31:17.583 | ERROR    |  7265 | mycroft.audio.speech:handle_speak:99 | Error in mute_and_speak
Traceback (most recent call last):
  File "/opt/mycroft-core/mycroft/audio/speech.py", line 95, in handle_speak
    mute_and_speak(chunk, ident, listen)
  File "/opt/mycroft-core/mycroft/audio/speech.py", line 120, in mute_and_speak
    tts.playback.stop()
AttributeError: 'NoneType' object has no attribute 'playback'
2021-10-23 09:31:17.584 | ERROR    |  7265 | mycroft.audio.speech:handle_speak:99 | Error in mute_and_speak
Traceback (most recent call last):
  File "/opt/mycroft-core/mycroft/audio/speech.py", line 95, in handle_speak
    mute_and_speak(chunk, ident, listen)
  File "/opt/mycroft-core/mycroft/audio/speech.py", line 120, in mute_and_speak
    tts.playback.stop()
AttributeError: 'NoneType' object has no attribute 'playback'
2021-10-23 09:31:17.585 | ERROR    |  7265 | mycroft.audio.speech:handle_speak:99 | Error in mute_and_speak
Traceback (most recent call last):
  File "/opt/mycroft-core/mycroft/audio/speech.py", line 95, in handle_speak
    mute_and_speak(chunk, ident, listen)
  File "/opt/mycroft-core/mycroft/audio/speech.py", line 120, in mute_and_speak
    tts.playback.stop()
AttributeError: 'NoneType' object has no attribute 'playback'
2021-10-23 09:31:17.585 | ERROR    |  7265 | mycroft.audio.speech:handle_speak:99 | Error in mute_and_speak
Traceback (most recent call last):
  File "/opt/mycroft-core/mycroft/audio/speech.py", line 95, in handle_speak
    mute_and_speak(chunk, ident, listen)
  File "/opt/mycroft-core/mycroft/audio/speech.py", line 120, in mute_and_speak
    tts.playback.stop()
AttributeError: 'NoneType' object has no attribute 'playback'
2021-10-23 09:31:25.232 | ERROR    |  7265 | mycroft.audio.speech:handle_speak:99 | Error in mute_and_speak
Traceback (most recent call last):
  File "/opt/mycroft-core/mycroft/audio/speech.py", line 95, in handle_speak
    mute_and_speak(chunk, ident, listen)
  File "/opt/mycroft-core/mycroft/audio/speech.py", line 120, in mute_and_speak
    tts.playback.stop()
AttributeError: 'NoneType' object has no attribute 'playback'
2021-10-23 09:31:25.897 | ERROR    |  7265 | mycroft.audio.speech:handle_speak:99 | Error in mute_and_speak
Traceback (most recent call last):
  File "/opt/mycroft-core/mycroft/audio/speech.py", line 95, in handle_speak
    mute_and_speak(chunk, ident, listen)
  File "/opt/mycroft-core/mycroft/audio/speech.py", line 120, in mute_and_speak
    tts.playback.stop()
AttributeError: 'NoneType' object has no attribute 'playback'
2021-10-23 09:31:26.264 | ERROR    |  7265 | mycroft.audio.speech:handle_speak:99 | Error in mute_and_speak
Traceback (most recent call last):
  File "/opt/mycroft-core/mycroft/audio/speech.py", line 95, in handle_speak
    mute_and_speak(chunk, ident, listen)
  File "/opt/mycroft-core/mycroft/audio/speech.py", line 120, in mute_and_speak
    tts.playback.stop()
AttributeError: 'NoneType' object has no attribute 'playback'
2021-10-23 09:31:26.922 | ERROR    |  7265 | mycroft.audio.speech:handle_speak:99 | Error in mute_and_speak
Traceback (most recent call last):
  File "/opt/mycroft-core/mycroft/audio/speech.py", line 95, in handle_speak
    mute_and_speak(chunk, ident, listen)
  File "/opt/mycroft-core/mycroft/audio/speech.py", line 120, in mute_and_speak
    tts.playback.stop()
AttributeError: 'NoneType' object has no attribute 'playback'
2021-10-23 09:31:27.299 | ERROR    |  7265 | mycroft.audio.speech:handle_speak:99 | Error in mute_and_speak
Traceback (most recent call last):
  File "/opt/mycroft-core/mycroft/audio/speech.py", line 95, in handle_speak
    mute_and_speak(chunk, ident, listen)
  File "/opt/mycroft-core/mycroft/audio/speech.py", line 120, in mute_and_speak
    tts.playback.stop()
AttributeError: 'NoneType' object has no attribute 'playback'
2021-10-23 09:31:28.314 | ERROR    |  7265 | mycroft.audio.speech:handle_speak:99 | Error in mute_and_speak
Traceback (most recent call last):
  File "/opt/mycroft-core/mycroft/audio/speech.py", line 95, in handle_speak
    mute_and_speak(chunk, ident, listen)
  File "/opt/mycroft-core/mycroft/audio/speech.py", line 120, in mute_and_speak
    tts.playback.stop()
AttributeError: 'NoneType' object has no attribute 'playback'
2021-10-23 09:31:29.352 | ERROR    |  7265 | mycroft.audio.speech:handle_speak:99 | Error in mute_and_speak
Traceback (most recent call last):
  File "/opt/mycroft-core/mycroft/audio/speech.py", line 95, in handle_speak
    mute_and_speak(chunk, ident, listen)
  File "/opt/mycroft-core/mycroft/audio/speech.py", line 120, in mute_and_speak
    tts.playback.stop()
AttributeError: 'NoneType' object has no attribute 'playback'
2021-10-23 09:31:35.654 | ERROR    |  7265 | mycroft.audio.speech:handle_speak:99 | Error in mute_and_speak
Traceback (most recent call last):
  File "/opt/mycroft-core/mycroft/audio/speech.py", line 95, in handle_speak
    mute_and_speak(chunk, ident, listen)
  File "/opt/mycroft-core/mycroft/audio/speech.py", line 120, in mute_and_speak
    tts.playback.stop()
AttributeError: 'NoneType' object has no attribute 'playback'
2021-10-23 09:31:36.352 | ERROR    |  7265 | mycroft.audio.speech:handle_speak:99 | Error in mute_and_speak
Traceback (most recent call last):
  File "/opt/mycroft-core/mycroft/audio/speech.py", line 95, in handle_speak
    mute_and_speak(chunk, ident, listen)
  File "/opt/mycroft-core/mycroft/audio/speech.py", line 120, in mute_and_speak
    tts.playback.stop()
AttributeError: 'NoneType' object has no attribute 'playback'
2021-10-23 09:31:36.994 | ERROR    |  7265 | mycroft.audio.speech:handle_speak:99 | Error in mute_and_speak
Traceback (most recent call last):
  File "/opt/mycroft-core/mycroft/audio/speech.py", line 95, in handle_speak
    mute_and_speak(chunk, ident, listen)
  File "/opt/mycroft-core/mycroft/audio/speech.py", line 120, in mute_and_speak
    tts.playback.stop()
AttributeError: 'NoneType' object has no attribute 'playback'
Exception ignored in: <module 'threading' from '/opt/hostedtoolcache/Python/3.7.12/x64/lib/python3.7/threading.py'>
Traceback (most recent call last):
  File "/opt/hostedtoolcache/Python/3.7.12/x64/lib/python3.7/threading.py", line 1307, in _shutdown
    lock.acquire()
KeyboardInterrupt
